[2025-05-19T23:05:04.172+0000] {processor.py:161} INFO - Started process (PID=73) to work on /opt/airflow/dags/exampledag.py
[2025-05-19T23:05:04.176+0000] {processor.py:830} INFO - Processing file /opt/airflow/dags/exampledag.py for tasks to queue
[2025-05-19T23:05:04.190+0000] {logging_mixin.py:188} INFO - [2025-05-19T23:05:04.188+0000] {dagbag.py:540} INFO - Filling up the DagBag from /opt/airflow/dags/exampledag.py
[2025-05-19T23:05:04.242+0000] {logging_mixin.py:188} INFO - [2025-05-19T23:05:04.235+0000] {dagbag.py:350} ERROR - Failed to import: /opt/airflow/dags/exampledag.py
Traceback (most recent call last):
  File "/home/airflow/.local/lib/python3.8/site-packages/airflow/models/dagbag.py", line 346, in parse
    loader.exec_module(new_module)
  File "<frozen importlib._bootstrap_external>", line 843, in exec_module
  File "<frozen importlib._bootstrap>", line 219, in _call_with_frames_removed
  File "/opt/airflow/dags/exampledag.py", line 23, in <module>
    from airflow import Asset
ImportError: cannot import name 'Asset' from 'airflow' (/home/airflow/.local/lib/python3.8/site-packages/airflow/__init__.py)
[2025-05-19T23:05:04.246+0000] {processor.py:842} WARNING - No viable dags retrieved from /opt/airflow/dags/exampledag.py
[2025-05-19T23:05:04.315+0000] {processor.py:183} INFO - Processing /opt/airflow/dags/exampledag.py took 0.164 seconds
[2025-05-19T23:05:34.664+0000] {processor.py:161} INFO - Started process (PID=129) to work on /opt/airflow/dags/exampledag.py
[2025-05-19T23:05:34.670+0000] {processor.py:830} INFO - Processing file /opt/airflow/dags/exampledag.py for tasks to queue
[2025-05-19T23:05:34.679+0000] {logging_mixin.py:188} INFO - [2025-05-19T23:05:34.678+0000] {dagbag.py:540} INFO - Filling up the DagBag from /opt/airflow/dags/exampledag.py
[2025-05-19T23:05:34.791+0000] {logging_mixin.py:188} INFO - [2025-05-19T23:05:34.767+0000] {dagbag.py:350} ERROR - Failed to import: /opt/airflow/dags/exampledag.py
Traceback (most recent call last):
  File "/home/airflow/.local/lib/python3.8/site-packages/airflow/models/dagbag.py", line 346, in parse
    loader.exec_module(new_module)
  File "<frozen importlib._bootstrap_external>", line 843, in exec_module
  File "<frozen importlib._bootstrap>", line 219, in _call_with_frames_removed
  File "/opt/airflow/dags/exampledag.py", line 23, in <module>
    from airflow import Asset
ImportError: cannot import name 'Asset' from 'airflow' (/home/airflow/.local/lib/python3.8/site-packages/airflow/__init__.py)
[2025-05-19T23:05:34.799+0000] {processor.py:842} WARNING - No viable dags retrieved from /opt/airflow/dags/exampledag.py
[2025-05-19T23:05:34.922+0000] {processor.py:183} INFO - Processing /opt/airflow/dags/exampledag.py took 0.273 seconds
[2025-05-19T23:06:05.784+0000] {processor.py:161} INFO - Started process (PID=186) to work on /opt/airflow/dags/exampledag.py
[2025-05-19T23:06:05.788+0000] {processor.py:830} INFO - Processing file /opt/airflow/dags/exampledag.py for tasks to queue
[2025-05-19T23:06:05.794+0000] {logging_mixin.py:188} INFO - [2025-05-19T23:06:05.793+0000] {dagbag.py:540} INFO - Filling up the DagBag from /opt/airflow/dags/exampledag.py
[2025-05-19T23:06:05.846+0000] {logging_mixin.py:188} INFO - [2025-05-19T23:06:05.836+0000] {dagbag.py:350} ERROR - Failed to import: /opt/airflow/dags/exampledag.py
Traceback (most recent call last):
  File "/home/airflow/.local/lib/python3.8/site-packages/airflow/models/dagbag.py", line 346, in parse
    loader.exec_module(new_module)
  File "<frozen importlib._bootstrap_external>", line 843, in exec_module
  File "<frozen importlib._bootstrap>", line 219, in _call_with_frames_removed
  File "/opt/airflow/dags/exampledag.py", line 23, in <module>
    from airflow import Asset
ImportError: cannot import name 'Asset' from 'airflow' (/home/airflow/.local/lib/python3.8/site-packages/airflow/__init__.py)
[2025-05-19T23:06:05.850+0000] {processor.py:842} WARNING - No viable dags retrieved from /opt/airflow/dags/exampledag.py
[2025-05-19T23:06:05.911+0000] {processor.py:183} INFO - Processing /opt/airflow/dags/exampledag.py took 0.136 seconds
[2025-05-19T23:06:36.139+0000] {processor.py:161} INFO - Started process (PID=243) to work on /opt/airflow/dags/exampledag.py
[2025-05-19T23:06:36.143+0000] {processor.py:830} INFO - Processing file /opt/airflow/dags/exampledag.py for tasks to queue
[2025-05-19T23:06:36.148+0000] {logging_mixin.py:188} INFO - [2025-05-19T23:06:36.148+0000] {dagbag.py:540} INFO - Filling up the DagBag from /opt/airflow/dags/exampledag.py
[2025-05-19T23:06:36.180+0000] {logging_mixin.py:188} INFO - [2025-05-19T23:06:36.173+0000] {dagbag.py:350} ERROR - Failed to import: /opt/airflow/dags/exampledag.py
Traceback (most recent call last):
  File "/home/airflow/.local/lib/python3.8/site-packages/airflow/models/dagbag.py", line 346, in parse
    loader.exec_module(new_module)
  File "<frozen importlib._bootstrap_external>", line 843, in exec_module
  File "<frozen importlib._bootstrap>", line 219, in _call_with_frames_removed
  File "/opt/airflow/dags/exampledag.py", line 23, in <module>
    from airflow import Asset
ImportError: cannot import name 'Asset' from 'airflow' (/home/airflow/.local/lib/python3.8/site-packages/airflow/__init__.py)
[2025-05-19T23:06:36.183+0000] {processor.py:842} WARNING - No viable dags retrieved from /opt/airflow/dags/exampledag.py
[2025-05-19T23:06:36.262+0000] {processor.py:183} INFO - Processing /opt/airflow/dags/exampledag.py took 0.130 seconds
[2025-05-19T23:07:06.557+0000] {processor.py:161} INFO - Started process (PID=300) to work on /opt/airflow/dags/exampledag.py
[2025-05-19T23:07:06.560+0000] {processor.py:830} INFO - Processing file /opt/airflow/dags/exampledag.py for tasks to queue
[2025-05-19T23:07:06.568+0000] {logging_mixin.py:188} INFO - [2025-05-19T23:07:06.567+0000] {dagbag.py:540} INFO - Filling up the DagBag from /opt/airflow/dags/exampledag.py
[2025-05-19T23:07:06.603+0000] {logging_mixin.py:188} INFO - [2025-05-19T23:07:06.596+0000] {dagbag.py:350} ERROR - Failed to import: /opt/airflow/dags/exampledag.py
Traceback (most recent call last):
  File "/home/airflow/.local/lib/python3.8/site-packages/airflow/models/dagbag.py", line 346, in parse
    loader.exec_module(new_module)
  File "<frozen importlib._bootstrap_external>", line 843, in exec_module
  File "<frozen importlib._bootstrap>", line 219, in _call_with_frames_removed
  File "/opt/airflow/dags/exampledag.py", line 23, in <module>
    from airflow import Asset
ImportError: cannot import name 'Asset' from 'airflow' (/home/airflow/.local/lib/python3.8/site-packages/airflow/__init__.py)
[2025-05-19T23:07:06.606+0000] {processor.py:842} WARNING - No viable dags retrieved from /opt/airflow/dags/exampledag.py
[2025-05-19T23:07:06.645+0000] {processor.py:183} INFO - Processing /opt/airflow/dags/exampledag.py took 0.104 seconds
[2025-05-19T23:07:36.966+0000] {processor.py:161} INFO - Started process (PID=357) to work on /opt/airflow/dags/exampledag.py
[2025-05-19T23:07:36.969+0000] {processor.py:830} INFO - Processing file /opt/airflow/dags/exampledag.py for tasks to queue
[2025-05-19T23:07:36.979+0000] {logging_mixin.py:188} INFO - [2025-05-19T23:07:36.975+0000] {dagbag.py:540} INFO - Filling up the DagBag from /opt/airflow/dags/exampledag.py
[2025-05-19T23:07:37.018+0000] {logging_mixin.py:188} INFO - [2025-05-19T23:07:37.007+0000] {dagbag.py:350} ERROR - Failed to import: /opt/airflow/dags/exampledag.py
Traceback (most recent call last):
  File "/home/airflow/.local/lib/python3.8/site-packages/airflow/models/dagbag.py", line 346, in parse
    loader.exec_module(new_module)
  File "<frozen importlib._bootstrap_external>", line 843, in exec_module
  File "<frozen importlib._bootstrap>", line 219, in _call_with_frames_removed
  File "/opt/airflow/dags/exampledag.py", line 23, in <module>
    from airflow import Asset
ImportError: cannot import name 'Asset' from 'airflow' (/home/airflow/.local/lib/python3.8/site-packages/airflow/__init__.py)
[2025-05-19T23:07:37.023+0000] {processor.py:842} WARNING - No viable dags retrieved from /opt/airflow/dags/exampledag.py
[2025-05-19T23:07:37.109+0000] {processor.py:183} INFO - Processing /opt/airflow/dags/exampledag.py took 0.155 seconds
[2025-05-19T23:08:07.904+0000] {processor.py:161} INFO - Started process (PID=414) to work on /opt/airflow/dags/exampledag.py
[2025-05-19T23:08:07.907+0000] {processor.py:830} INFO - Processing file /opt/airflow/dags/exampledag.py for tasks to queue
[2025-05-19T23:08:07.913+0000] {logging_mixin.py:188} INFO - [2025-05-19T23:08:07.912+0000] {dagbag.py:540} INFO - Filling up the DagBag from /opt/airflow/dags/exampledag.py
[2025-05-19T23:08:07.958+0000] {logging_mixin.py:188} INFO - [2025-05-19T23:08:07.949+0000] {dagbag.py:350} ERROR - Failed to import: /opt/airflow/dags/exampledag.py
Traceback (most recent call last):
  File "/home/airflow/.local/lib/python3.8/site-packages/airflow/models/dagbag.py", line 346, in parse
    loader.exec_module(new_module)
  File "<frozen importlib._bootstrap_external>", line 843, in exec_module
  File "<frozen importlib._bootstrap>", line 219, in _call_with_frames_removed
  File "/opt/airflow/dags/exampledag.py", line 23, in <module>
    from airflow import Asset
ImportError: cannot import name 'Asset' from 'airflow' (/home/airflow/.local/lib/python3.8/site-packages/airflow/__init__.py)
[2025-05-19T23:08:07.962+0000] {processor.py:842} WARNING - No viable dags retrieved from /opt/airflow/dags/exampledag.py
[2025-05-19T23:08:08.061+0000] {processor.py:183} INFO - Processing /opt/airflow/dags/exampledag.py took 0.186 seconds
[2025-05-19T23:08:38.327+0000] {processor.py:161} INFO - Started process (PID=471) to work on /opt/airflow/dags/exampledag.py
[2025-05-19T23:08:38.330+0000] {processor.py:830} INFO - Processing file /opt/airflow/dags/exampledag.py for tasks to queue
[2025-05-19T23:08:38.335+0000] {logging_mixin.py:188} INFO - [2025-05-19T23:08:38.334+0000] {dagbag.py:540} INFO - Filling up the DagBag from /opt/airflow/dags/exampledag.py
[2025-05-19T23:08:38.371+0000] {logging_mixin.py:188} INFO - [2025-05-19T23:08:38.364+0000] {dagbag.py:350} ERROR - Failed to import: /opt/airflow/dags/exampledag.py
Traceback (most recent call last):
  File "/home/airflow/.local/lib/python3.8/site-packages/airflow/models/dagbag.py", line 346, in parse
    loader.exec_module(new_module)
  File "<frozen importlib._bootstrap_external>", line 843, in exec_module
  File "<frozen importlib._bootstrap>", line 219, in _call_with_frames_removed
  File "/opt/airflow/dags/exampledag.py", line 23, in <module>
    from airflow import Asset
ImportError: cannot import name 'Asset' from 'airflow' (/home/airflow/.local/lib/python3.8/site-packages/airflow/__init__.py)
[2025-05-19T23:08:38.374+0000] {processor.py:842} WARNING - No viable dags retrieved from /opt/airflow/dags/exampledag.py
[2025-05-19T23:08:38.422+0000] {processor.py:183} INFO - Processing /opt/airflow/dags/exampledag.py took 0.107 seconds
[2025-05-19T23:09:08.557+0000] {processor.py:161} INFO - Started process (PID=528) to work on /opt/airflow/dags/exampledag.py
[2025-05-19T23:09:08.561+0000] {processor.py:830} INFO - Processing file /opt/airflow/dags/exampledag.py for tasks to queue
[2025-05-19T23:09:08.574+0000] {logging_mixin.py:188} INFO - [2025-05-19T23:09:08.573+0000] {dagbag.py:540} INFO - Filling up the DagBag from /opt/airflow/dags/exampledag.py
[2025-05-19T23:09:08.612+0000] {logging_mixin.py:188} INFO - [2025-05-19T23:09:08.602+0000] {dagbag.py:350} ERROR - Failed to import: /opt/airflow/dags/exampledag.py
Traceback (most recent call last):
  File "/home/airflow/.local/lib/python3.8/site-packages/airflow/models/dagbag.py", line 346, in parse
    loader.exec_module(new_module)
  File "<frozen importlib._bootstrap_external>", line 843, in exec_module
  File "<frozen importlib._bootstrap>", line 219, in _call_with_frames_removed
  File "/opt/airflow/dags/exampledag.py", line 23, in <module>
    from airflow import Asset
ImportError: cannot import name 'Asset' from 'airflow' (/home/airflow/.local/lib/python3.8/site-packages/airflow/__init__.py)
[2025-05-19T23:09:08.616+0000] {processor.py:842} WARNING - No viable dags retrieved from /opt/airflow/dags/exampledag.py
[2025-05-19T23:09:08.687+0000] {processor.py:183} INFO - Processing /opt/airflow/dags/exampledag.py took 0.145 seconds
[2025-05-19T23:09:39.677+0000] {processor.py:161} INFO - Started process (PID=586) to work on /opt/airflow/dags/exampledag.py
[2025-05-19T23:09:39.682+0000] {processor.py:830} INFO - Processing file /opt/airflow/dags/exampledag.py for tasks to queue
[2025-05-19T23:09:39.686+0000] {logging_mixin.py:188} INFO - [2025-05-19T23:09:39.685+0000] {dagbag.py:540} INFO - Filling up the DagBag from /opt/airflow/dags/exampledag.py
[2025-05-19T23:09:39.727+0000] {logging_mixin.py:188} INFO - [2025-05-19T23:09:39.718+0000] {dagbag.py:350} ERROR - Failed to import: /opt/airflow/dags/exampledag.py
Traceback (most recent call last):
  File "/home/airflow/.local/lib/python3.8/site-packages/airflow/models/dagbag.py", line 346, in parse
    loader.exec_module(new_module)
  File "<frozen importlib._bootstrap_external>", line 843, in exec_module
  File "<frozen importlib._bootstrap>", line 219, in _call_with_frames_removed
  File "/opt/airflow/dags/exampledag.py", line 23, in <module>
    from airflow import Asset
ImportError: cannot import name 'Asset' from 'airflow' (/home/airflow/.local/lib/python3.8/site-packages/airflow/__init__.py)
[2025-05-19T23:09:39.730+0000] {processor.py:842} WARNING - No viable dags retrieved from /opt/airflow/dags/exampledag.py
[2025-05-19T23:09:39.786+0000] {processor.py:183} INFO - Processing /opt/airflow/dags/exampledag.py took 0.116 seconds
[2025-05-19T23:10:10.374+0000] {processor.py:161} INFO - Started process (PID=643) to work on /opt/airflow/dags/exampledag.py
[2025-05-19T23:10:10.379+0000] {processor.py:830} INFO - Processing file /opt/airflow/dags/exampledag.py for tasks to queue
[2025-05-19T23:10:10.386+0000] {logging_mixin.py:188} INFO - [2025-05-19T23:10:10.385+0000] {dagbag.py:540} INFO - Filling up the DagBag from /opt/airflow/dags/exampledag.py
[2025-05-19T23:10:10.430+0000] {logging_mixin.py:188} INFO - [2025-05-19T23:10:10.422+0000] {dagbag.py:350} ERROR - Failed to import: /opt/airflow/dags/exampledag.py
Traceback (most recent call last):
  File "/home/airflow/.local/lib/python3.8/site-packages/airflow/models/dagbag.py", line 346, in parse
    loader.exec_module(new_module)
  File "<frozen importlib._bootstrap_external>", line 843, in exec_module
  File "<frozen importlib._bootstrap>", line 219, in _call_with_frames_removed
  File "/opt/airflow/dags/exampledag.py", line 23, in <module>
    from airflow import Asset
ImportError: cannot import name 'Asset' from 'airflow' (/home/airflow/.local/lib/python3.8/site-packages/airflow/__init__.py)
[2025-05-19T23:10:10.433+0000] {processor.py:842} WARNING - No viable dags retrieved from /opt/airflow/dags/exampledag.py
[2025-05-19T23:10:10.490+0000] {processor.py:183} INFO - Processing /opt/airflow/dags/exampledag.py took 0.133 seconds
[2025-05-19T23:10:41.190+0000] {processor.py:161} INFO - Started process (PID=700) to work on /opt/airflow/dags/exampledag.py
[2025-05-19T23:10:41.194+0000] {processor.py:830} INFO - Processing file /opt/airflow/dags/exampledag.py for tasks to queue
[2025-05-19T23:10:41.203+0000] {logging_mixin.py:188} INFO - [2025-05-19T23:10:41.202+0000] {dagbag.py:540} INFO - Filling up the DagBag from /opt/airflow/dags/exampledag.py
[2025-05-19T23:10:41.246+0000] {logging_mixin.py:188} INFO - [2025-05-19T23:10:41.238+0000] {dagbag.py:350} ERROR - Failed to import: /opt/airflow/dags/exampledag.py
Traceback (most recent call last):
  File "/home/airflow/.local/lib/python3.8/site-packages/airflow/models/dagbag.py", line 346, in parse
    loader.exec_module(new_module)
  File "<frozen importlib._bootstrap_external>", line 843, in exec_module
  File "<frozen importlib._bootstrap>", line 219, in _call_with_frames_removed
  File "/opt/airflow/dags/exampledag.py", line 23, in <module>
    from airflow import Asset
ImportError: cannot import name 'Asset' from 'airflow' (/home/airflow/.local/lib/python3.8/site-packages/airflow/__init__.py)
[2025-05-19T23:10:41.250+0000] {processor.py:842} WARNING - No viable dags retrieved from /opt/airflow/dags/exampledag.py
[2025-05-19T23:10:41.294+0000] {processor.py:183} INFO - Processing /opt/airflow/dags/exampledag.py took 0.117 seconds
[2025-05-19T23:12:23.951+0000] {processor.py:161} INFO - Started process (PID=758) to work on /opt/airflow/dags/exampledag.py
[2025-05-19T23:12:23.967+0000] {processor.py:830} INFO - Processing file /opt/airflow/dags/exampledag.py for tasks to queue
[2025-05-19T23:12:23.989+0000] {logging_mixin.py:188} INFO - [2025-05-19T23:12:23.987+0000] {dagbag.py:540} INFO - Filling up the DagBag from /opt/airflow/dags/exampledag.py
[2025-05-19T23:12:25.023+0000] {logging_mixin.py:188} INFO - [2025-05-19T23:12:24.884+0000] {dagbag.py:350} ERROR - Failed to import: /opt/airflow/dags/exampledag.py
Traceback (most recent call last):
  File "/home/airflow/.local/lib/python3.8/site-packages/airflow/models/dagbag.py", line 346, in parse
    loader.exec_module(new_module)
  File "<frozen importlib._bootstrap_external>", line 843, in exec_module
  File "<frozen importlib._bootstrap>", line 219, in _call_with_frames_removed
  File "/opt/airflow/dags/exampledag.py", line 23, in <module>
    from airflow import Asset
ImportError: cannot import name 'Asset' from 'airflow' (/home/airflow/.local/lib/python3.8/site-packages/airflow/__init__.py)
[2025-05-19T23:12:25.031+0000] {processor.py:842} WARNING - No viable dags retrieved from /opt/airflow/dags/exampledag.py
[2025-05-19T23:12:52.105+0000] {processor.py:186} ERROR - Got an exception! Propagating...
Traceback (most recent call last):
  File "/home/airflow/.local/lib/python3.8/site-packages/sqlalchemy/engine/base.py", line 3371, in _wrap_pool_connect
    return fn()
  File "/home/airflow/.local/lib/python3.8/site-packages/sqlalchemy/pool/base.py", line 327, in connect
    return _ConnectionFairy._checkout(self)
  File "/home/airflow/.local/lib/python3.8/site-packages/sqlalchemy/pool/base.py", line 894, in _checkout
    fairy = _ConnectionRecord.checkout(pool)
  File "/home/airflow/.local/lib/python3.8/site-packages/sqlalchemy/pool/base.py", line 493, in checkout
    rec = pool._do_get()
  File "/home/airflow/.local/lib/python3.8/site-packages/sqlalchemy/pool/impl.py", line 146, in _do_get
    self._dec_overflow()
  File "/home/airflow/.local/lib/python3.8/site-packages/sqlalchemy/util/langhelpers.py", line 70, in __exit__
    compat.raise_(
  File "/home/airflow/.local/lib/python3.8/site-packages/sqlalchemy/util/compat.py", line 211, in raise_
    raise exception
  File "/home/airflow/.local/lib/python3.8/site-packages/sqlalchemy/pool/impl.py", line 143, in _do_get
    return self._create_connection()
  File "/home/airflow/.local/lib/python3.8/site-packages/sqlalchemy/pool/base.py", line 273, in _create_connection
    return _ConnectionRecord(self)
  File "/home/airflow/.local/lib/python3.8/site-packages/sqlalchemy/pool/base.py", line 388, in __init__
    self.__connect()
  File "/home/airflow/.local/lib/python3.8/site-packages/sqlalchemy/pool/base.py", line 691, in __connect
    pool.logger.debug("Error on connect(): %s", e)
  File "/home/airflow/.local/lib/python3.8/site-packages/sqlalchemy/util/langhelpers.py", line 70, in __exit__
    compat.raise_(
  File "/home/airflow/.local/lib/python3.8/site-packages/sqlalchemy/util/compat.py", line 211, in raise_
    raise exception
  File "/home/airflow/.local/lib/python3.8/site-packages/sqlalchemy/pool/base.py", line 686, in __connect
    self.dbapi_connection = connection = pool._invoke_creator(self)
  File "/home/airflow/.local/lib/python3.8/site-packages/sqlalchemy/engine/create.py", line 574, in connect
    return dialect.connect(*cargs, **cparams)
  File "/home/airflow/.local/lib/python3.8/site-packages/sqlalchemy/engine/default.py", line 598, in connect
    return self.dbapi.connect(*cargs, **cparams)
  File "/home/airflow/.local/lib/python3.8/site-packages/psycopg2/__init__.py", line 122, in connect
    conn = _connect(dsn, connection_factory=connection_factory, **kwasync)
psycopg2.OperationalError: could not translate host name "postgres" to address: Temporary failure in name resolution


The above exception was the direct cause of the following exception:

Traceback (most recent call last):
  File "/home/airflow/.local/lib/python3.8/site-packages/airflow/dag_processing/processor.py", line 182, in _run_file_processor
    _handle_dag_file_processing()
  File "/home/airflow/.local/lib/python3.8/site-packages/airflow/dag_processing/processor.py", line 163, in _handle_dag_file_processing
    result: tuple[int, int] = dag_file_processor.process_file(
  File "/home/airflow/.local/lib/python3.8/site-packages/airflow/utils/session.py", line 79, in wrapper
    return func(*args, session=session, **kwargs)
  File "/home/airflow/.local/lib/python3.8/site-packages/airflow/dag_processing/processor.py", line 843, in process_file
    DagFileProcessor.update_import_errors(
  File "/home/airflow/.local/lib/python3.8/site-packages/airflow/api_internal/internal_api_call.py", line 114, in wrapper
    return func(*args, **kwargs)
  File "/home/airflow/.local/lib/python3.8/site-packages/airflow/utils/session.py", line 76, in wrapper
    return func(*args, **kwargs)
  File "/home/airflow/.local/lib/python3.8/site-packages/airflow/dag_processing/processor.py", line 622, in update_import_errors
    existing_import_error_files = [x.filename for x in session.query(errors.ImportError.filename).all()]
  File "/home/airflow/.local/lib/python3.8/site-packages/sqlalchemy/orm/query.py", line 2773, in all
    return self._iter().all()
  File "/home/airflow/.local/lib/python3.8/site-packages/sqlalchemy/orm/query.py", line 2916, in _iter
    result = self.session.execute(
  File "/home/airflow/.local/lib/python3.8/site-packages/sqlalchemy/orm/session.py", line 1716, in execute
    conn = self._connection_for_bind(bind)
  File "/home/airflow/.local/lib/python3.8/site-packages/sqlalchemy/orm/session.py", line 1555, in _connection_for_bind
    return self._transaction._connection_for_bind(
  File "/home/airflow/.local/lib/python3.8/site-packages/sqlalchemy/orm/session.py", line 750, in _connection_for_bind
    conn = bind.connect()
  File "/home/airflow/.local/lib/python3.8/site-packages/sqlalchemy/future/engine.py", line 412, in connect
    return super(Engine, self).connect()
  File "/home/airflow/.local/lib/python3.8/site-packages/sqlalchemy/engine/base.py", line 3325, in connect
    return self._connection_cls(self, close_with_result=close_with_result)
  File "/home/airflow/.local/lib/python3.8/site-packages/sqlalchemy/engine/base.py", line 96, in __init__
    else engine.raw_connection()
  File "/home/airflow/.local/lib/python3.8/site-packages/sqlalchemy/engine/base.py", line 3404, in raw_connection
    return self._wrap_pool_connect(self.pool.connect, _connection)
  File "/home/airflow/.local/lib/python3.8/site-packages/sqlalchemy/engine/base.py", line 3374, in _wrap_pool_connect
    Connection._handle_dbapi_exception_noconnection(
  File "/home/airflow/.local/lib/python3.8/site-packages/sqlalchemy/engine/base.py", line 2208, in _handle_dbapi_exception_noconnection
    util.raise_(
  File "/home/airflow/.local/lib/python3.8/site-packages/sqlalchemy/util/compat.py", line 211, in raise_
    raise exception
  File "/home/airflow/.local/lib/python3.8/site-packages/sqlalchemy/engine/base.py", line 3371, in _wrap_pool_connect
    return fn()
  File "/home/airflow/.local/lib/python3.8/site-packages/sqlalchemy/pool/base.py", line 327, in connect
    return _ConnectionFairy._checkout(self)
  File "/home/airflow/.local/lib/python3.8/site-packages/sqlalchemy/pool/base.py", line 894, in _checkout
    fairy = _ConnectionRecord.checkout(pool)
  File "/home/airflow/.local/lib/python3.8/site-packages/sqlalchemy/pool/base.py", line 493, in checkout
    rec = pool._do_get()
  File "/home/airflow/.local/lib/python3.8/site-packages/sqlalchemy/pool/impl.py", line 146, in _do_get
    self._dec_overflow()
  File "/home/airflow/.local/lib/python3.8/site-packages/sqlalchemy/util/langhelpers.py", line 70, in __exit__
    compat.raise_(
  File "/home/airflow/.local/lib/python3.8/site-packages/sqlalchemy/util/compat.py", line 211, in raise_
    raise exception
  File "/home/airflow/.local/lib/python3.8/site-packages/sqlalchemy/pool/impl.py", line 143, in _do_get
    return self._create_connection()
  File "/home/airflow/.local/lib/python3.8/site-packages/sqlalchemy/pool/base.py", line 273, in _create_connection
    return _ConnectionRecord(self)
  File "/home/airflow/.local/lib/python3.8/site-packages/sqlalchemy/pool/base.py", line 388, in __init__
    self.__connect()
  File "/home/airflow/.local/lib/python3.8/site-packages/sqlalchemy/pool/base.py", line 691, in __connect
    pool.logger.debug("Error on connect(): %s", e)
  File "/home/airflow/.local/lib/python3.8/site-packages/sqlalchemy/util/langhelpers.py", line 70, in __exit__
    compat.raise_(
  File "/home/airflow/.local/lib/python3.8/site-packages/sqlalchemy/util/compat.py", line 211, in raise_
    raise exception
  File "/home/airflow/.local/lib/python3.8/site-packages/sqlalchemy/pool/base.py", line 686, in __connect
    self.dbapi_connection = connection = pool._invoke_creator(self)
  File "/home/airflow/.local/lib/python3.8/site-packages/sqlalchemy/engine/create.py", line 574, in connect
    return dialect.connect(*cargs, **cparams)
  File "/home/airflow/.local/lib/python3.8/site-packages/sqlalchemy/engine/default.py", line 598, in connect
    return self.dbapi.connect(*cargs, **cparams)
  File "/home/airflow/.local/lib/python3.8/site-packages/psycopg2/__init__.py", line 122, in connect
    conn = _connect(dsn, connection_factory=connection_factory, **kwasync)
sqlalchemy.exc.OperationalError: (psycopg2.OperationalError) could not translate host name "postgres" to address: Temporary failure in name resolution

(Background on this error at: https://sqlalche.me/e/14/e3q8)
[2025-05-19T23:45:25.768+0000] {processor.py:161} INFO - Started process (PID=204) to work on /opt/airflow/dags/exampledag.py
[2025-05-19T23:45:25.880+0000] {processor.py:830} INFO - Processing file /opt/airflow/dags/exampledag.py for tasks to queue
[2025-05-19T23:45:25.913+0000] {logging_mixin.py:188} INFO - [2025-05-19T23:45:25.909+0000] {dagbag.py:540} INFO - Filling up the DagBag from /opt/airflow/dags/exampledag.py
[2025-05-19T23:45:28.126+0000] {logging_mixin.py:188} INFO - [2025-05-19T23:45:28.023+0000] {dagbag.py:350} ERROR - Failed to import: /opt/airflow/dags/exampledag.py
Traceback (most recent call last):
  File "/home/airflow/.local/lib/python3.8/site-packages/airflow/models/dagbag.py", line 346, in parse
    loader.exec_module(new_module)
  File "<frozen importlib._bootstrap_external>", line 843, in exec_module
  File "<frozen importlib._bootstrap>", line 219, in _call_with_frames_removed
  File "/opt/airflow/dags/exampledag.py", line 23, in <module>
    from airflow import Asset
ImportError: cannot import name 'Asset' from 'airflow' (/home/airflow/.local/lib/python3.8/site-packages/airflow/__init__.py)
[2025-05-19T23:45:28.149+0000] {processor.py:842} WARNING - No viable dags retrieved from /opt/airflow/dags/exampledag.py
[2025-05-19T23:45:29.260+0000] {processor.py:183} INFO - Processing /opt/airflow/dags/exampledag.py took 3.616 seconds
